Workbook

Sheet Designações ()
B1: DESIGNAÇÕES MECÂNICAS | N1: INDICADORES | O1: MIC. VOL. | P1: PALCO | Q1: MIDIA | R1: ANFITRIÕES | S1: LEITORES | T1: PRESIDENTES | W1: INDICADORES | X1: MIC. VOL. | Y1: PALCO | Z1: MIDIA | AA1: ANFITRIÕES | AB1: LEITORES | AC1: PRESIDENTES | AF1: INDICADORES | AG1: MIC. VOL. | AH1: PALCO | AI1: MIDIA | AJ1: ANFITRIÕES | AK1: LEITORES | AL1: PRESIDENTES
K2: REUNIÃO FINAL DE SEM.
B3: DATA | C3: INDICADOR | E3: MICROFONE | G3: PALCO | H3: MIDIA | I3: ANFITRIÃO (ZOOM) | K3: PRESIDENTE | L3: LEITOR
B4: 01 / 10 | C4: PETRÚCIO | D4: MOISÉS | E4: TÉRCIO | F4: DANIEL | G4: DENILSON | H4: JEAN LUCAS | I4: JHOSEF | K4: ='Designações FDS ()'!J3 -> Almir Fernandes | L4: ='Designações FDS ()'!K3 -> BRUNO REIS | T4: AILTON | V4: 1 | AC4: 1 | AE4: =RAND() -> 0.88053741 | AL4: 1 | AN4: 1 | AO4: AILTON
B5: 05 / 10 | C5: TÉRCIO | D5: MOSES | E5: DENILSON | F5: JACKSON | G5: DANIEL | H5: JHOSEF | I5: JEAN LUCAS | T5: DENIS | V5: 2 | AC5: 2 | AE5: =RAND() -> 0.58960253 | AL5: 2 | AN5: 2 | AO5: DENIS
B6: 08 / 10 | C6: DENILSON | D6: PETRÚCIO | E6: DANIEL | F6: GASPAR | G6: LEONEL | H6: JOÃO CARLOS | I6: BRUNO REIS | K6: ='Designações FDS ()'!J5 -> Denis Pereira | L6: ='Designações FDS ()'!K5 -> JEAN LUCAS | T6: VITOR MEDEIROS | V6: 3 | AC6: 3 | AE6: =RAND() -> 0.0013228422 | AL6: 3 | AN6: 3 | AO6: VITOR MEDEIROS
B7: 12 / 10 | C7: EDVALDO | D7: DENILSON | E7: LEONEL | F7: DAVID | G7: MOISÉS | H7: BRUNO REIS | I7: FRED PACHECO | T7: FABRÍCIO | V7: 4 | AC7: 4 | AE7: =RAND() -> 0.064670599 | AL7: 4 | AN7: 4 | AO7: FABRÍCIO
B8: 15 / 10 | C8: INÁCIO | D8: TÉRCIO | E8: MOISÉS | F8: DENILSON | G8: MAURICIO | H8: FRED PACHECO | I8: JOÃO CARLOS | K8: ='Designações FDS ()'!J7 -> BRUNO REIS | L8: ='Designações FDS ()'!K7 -> LEONEL | T8: LEONILDO | V8: 5 | AC8: 5 | AE8: =RAND() -> 0.566343 | AL8: 5 | AN8: 5 | AO8: LEONILDO
B9: 19 / 10 | C9: ISRAEL F. | D9: EDVALDO | E9: MAURICIO | F9: DANIEL | G9: INÁCIO | H9: VÍTOR HUGO | I9: JEAN LUCAS | T9: ADÃO | V9: 6 | AC9: 6 | AE9: =RAND() -> 0.56415251 | AL9: 6 | AN9: 6 | AO9: ADÃO
B10: 22 / 10 | C10: JACKSON | D10: FRED PACHECO | E10: TÉRCIO | F10: LEONEL | G10: ISRAEL F. | H10: MOSES | I10: JHOSEF | K10: ='Designações FDS ()'!J9 -> JEAN LUCAS | L10: ='Designações FDS ()'!K9 -> VÍTOR HUGO | T10: EDUARDO | V10: 7 | AC10: 7 | AE10: =RAND() -> 0.022907528 | AL10: 7 | AN10: 7 | AO10: EDUARDO
B11: 26 / 10 | C11: MAURICIO | D11: INÁCIO | E11: ISRAEL F. | F11: MOISÉS | G11: TÉRCIO | H11: JOÃO CARLOS | I11: BRUNO REIS | T11: FABIANO | V11: 8 | AC11: 8 | AE11: =RAND() -> 0.87481092 | AL11: 8 | AN11: 8 | AO11: FABIANO
B12: 29 / 10 | C12: LEONEL | D12: ISRAEL F. | E12: INÁCIO | F12: MAURICIO | G12: EDVALDO | H12: JHOSEF | I12: VÍTOR HUGO | K12: ='Designações FDS ()'!J11 -> Vitor Medeiros | L12: ='Designações FDS ()'!K11 -> FRED PACHECO | T12: LÚCIO | V12: 9 | AC12: 9 | AE12: =RAND() -> 0.15021711 | AL12: 9 | AN12: 9 | AO12: LÚCIO
B13: 02 / 11 | C13: MOISÉS | D13: JACKSON | E13: EDVALDO | F13: TÉRCIO | G13: PETRÚCIO | H13: JEAN LUCAS | I13: FRED PACHECO | T13: WALDINES | V13: 10 | AC13: 10 | AE13: =RAND() -> 0.19379175 | AL13: 10 | AN13: 10 | AO13: WALDINES
B14: 05 / 11 | C14: LEONEL | D14: JEAN LUCAS | E14: PETRÚCIO | F14: ISRAEL F. | G14: JACKSON | H14: DANIEL | I14: MOSES | K14: ='Designações FDS ()'!J13 -> José Jhosef | L14: ='Designações FDS ()'!K13 -> DENILSON | T14: GEORGETOWN | V14: 11 | AC14: 11 | AE14: =RAND() -> 0.36063553 | AL14: 11 | AN14: 11 | AO14: GEORGETOWN
B15: 09 / 11 | C15: MAURICIO | D15: JHOSEF | E15: JACKSON | F15: INÁCIO | G15: GASPAR | H15: BRUNO REIS | I15: JOÃO CARLOS | T15: OLIVEIROS | V15: 12 | AC15: 12 | AE15: =RAND() -> 0.3607027 | AL15: 12 | AN15: 12 | AO15: OLIVEIROS
B16: 12 / 11 | C16: MOISÉS | D16: JOÃO CARLOS | E16: GASPAR | F16: EDVALDO | G16: DENILSON | H16: FRED PACHECO | I16: JHOSEF | K16: ='Designações FDS ()'!J15 -> Fabrício Félix | L16: ='Designações FDS ()'!K15 -> BRUNO REIS | T16: ALMIR | V16: 13 | AC16: 13 | AE16: =RAND() -> 0.40445563 | AL16: 13 | AN16: 13 | AO16: ALMIR
B17: 16 / 11 | C17: TÉRCIO | D17: LEONEL | E17: DAVID | F17: PETRÚCIO | G17: DANIEL | H17: DENILSON | I17: JEAN LUCAS | N17: JOÃO CARLOS | O17: JOÃO CARLOS | P17: JOÃO CARLOS | Q17: JOÃO CARLOS | R17: JOÃO CARLOS | S17: JOÃO CARLOS | T17: JOÃO CARLOS | V17: 14 | W17: 14 | X17: 14 | Y17: 14 | Z17: 14 | AA17: 14 | AB17: 14 | AC17: 14 | AE17: =RAND() -> 0.68304795 | AF17: 14 | AG17: 14 | AH17: 14 | AI17: 14 | AJ17: 14 | AK17: 14 | AL17: 14 | AN17: 14 | AO17: JOÃO CARLOS
B18: 19 / 11 | C18: PETRÚCIO | D18: MAURICIO | E18: ISRAEL F. | F18: DENILSON | G18: LEONEL | H18: VÍTOR HUGO | I18: BRUNO REIS | K18: ='Designações FDS ()'!J17 -> Maurício Bello | L18: ='Designações FDS ()'!K17 -> JOÃO CARLOS | N18: BRUNO REIS | O18: BRUNO REIS | P18: BRUNO REIS | Q18: BRUNO REIS | R18: BRUNO REIS | S18: BRUNO REIS | T18: BRUNO REIS | V18: 15 | W18: 15 | X18: 15 | Y18: 15 | Z18: 15 | AA18: 15 | AB18: 15 | AC18: 15 | AE18: =RAND() -> 0.17036493 | AF18: 15 | AG18: 15 | AH18: 15 | AI18: 15 | AJ18: 15 | AK18: 15 | AL18: 15 | AN18: 15 | AO18: BRUNO REIS
B19: 23 / 11 | C19: DENILSON | D19: JHOSEF | E19: INÁCIO | F19: DANIEL | G19: MOISÉS | H19: MOSES | I19: FRED PACHECO | N19: JEAN LUCAS | O19: JEAN LUCAS | P19: JEAN LUCAS | Q19: JEAN LUCAS | R19: JEAN LUCAS | S19: JEAN LUCAS | T19: JEAN LUCAS | V19: 16 | W19: 16 | X19: 16 | Y19: 16 | Z19: 16 | AA19: 16 | AB19: 16 | AC19: 16 | AE19: =RAND() -> 0.77155534 | AF19: 16 | AG19: 16 | AH19: 16 | AI19: 16 | AJ19: 16 | AK19: 16 | AL19: 16 | AN19: 16 | AO19: JEAN LUCAS
B20: 26 / 11 | C20: EDVALDO | D20: JOÃO CARLOS | E20: PETRÚCIO | F20: LEONEL | G20: MAURICIO | H20: JHOSEF | I20: VÍTOR HUGO | K20: ='Designações FDS ()'!J19 -> Leonildo Jr. | L20: ='Designações FDS ()'!K19 -> JEAN LUCAS | N20: LEONEL | O20: LEONEL | P20: LEONEL | S20: LEONEL | T20: LEONEL | V20: 17 | W20: 17 | X20: 17 | Y20: 17 | AB20: 17 | AC20: 17 | AE20: =RAND() -> 0.13909111 | AF20: 17 | AG20: 17 | AH20: 17 | AK20: 17 | AL20: 17 | AN20: 17 | AO20: LEONEL
B21: 30 / 11 | C21: INÁCIO | D21: LEONEL | E21: EDVALDO | F21: MOISÉS | G21: ISRAEL F. | H21: JOÃO CARLOS | I21: MOSES | N21: JHOSEF | O21: JHOSEF | P21: JHOSEF | Q21: JHOSEF | R21: JHOSEF | T21: JHOSEF | V21: 18 | W21: 18 | X21: 18 | Y21: 18 | Z21: 18 | AA21: 18 | AC21: 18 | AE21: =RAND() -> 0.43459134 | AF21: 18 | AG21: 18 | AH21: 18 | AI21: 18 | AJ21: 18 | AL21: 18 | AN21: 18 | AO21: JHOSEF
B22: 03 / 12 | C22: ISRAEL F. | D22: MAURICIO | E22: JACKSON | F22: INÁCIO | G22: TÉRCIO | H22: JEAN LUCAS | I22: JOÃO CARLOS | K22: ='Designações FDS ()'!J21 -> Adão Pereira | L22: ='Designações FDS ()'!K21 -> LEONEL | N22: MOISÉS | O22: MOISÉS | P22: MOISÉS | T22: MOISÉS | V22: 19 | W22: 19 | X22: 19 | Y22: 19 | AC22: 19 | AE22: =RAND() -> 0.38161132 | AF22: 19 | AG22: 19 | AH22: 19 | AL22: 19 | AN22: 19 | AO22: MOISÉS
B23: 07 / 12 | C23: JACKSON | D23: MOISÉS | E23: GASPAR | F23: TÉRCIO | G23: INÁCIO | H23: BRUNO REIS | I23: JHOSEF | N23: MAURICIO | O23: MAURICIO | P23: MAURICIO | T23: MAURÍCIO | V23: 20 | W23: 20 | X23: 20 | Y23: 20 | AC23: 20 | AE23: =RAND() -> 0.44860968 | AF23: 20 | AG23: 20 | AH23: 20 | AL23: 20 | AN23: 20 | AO23: MAURÍCIO
B24: 10 / 12 | C24: PETRÚCIO | D24: MOSES | E24: DAVID | F24: ISRAEL F. | G24: EDVALDO | H24: DANIEL | I24: JEAN LUCAS | K24: ='Designações FDS ()'!J23 -> Tércio Almeida | L24: ='Designações FDS ()'!K23 -> VÍTOR HUGO | N24: TÉRCIO | O24: TÉRCIO | P24: TÉRCIO | T24: TÉRCIO | V24: 21 | W24: 21 | X24: 21 | Y24: 21 | AC24: 21 | AE24: =RAND() -> 0.93982391 | AF24: 21 | AG24: 21 | AH24: 21 | AL24: 21 | AN24: 21 | AO24: TÉRCIO
B25: 14 / 12 | C25: TÉRCIO | D25: PETRÚCIO | E25: LEONEL | F25: MAURICIO | G25: DENILSON | H25: FRED PACHECO | I25: BRUNO REIS | N25: ISRAEL F. | O25: ISRAEL F. | P25: ISRAEL F. | V25: 22 | W25: 22 | X25: 22 | Y25: 22 | AE25: =RAND() -> 0.35482262 | AF25: 22 | AG25: 22 | AH25: 22 | AN25: 22 | AO25: ISRAEL F.
B26: 17 / 12 | C26: ISRAEL F. | D26: TÉRCIO | E26: DANIEL | F26: EDVALDO | G26: JACKSON | H26: DENILSON | I26: JOÃO CARLOS | K26: ='Designações FDS ()'!J25 -> Eduardo Cato | L26: ='Designações FDS ()'!K25 -> FRED PACHECO | N26: FRED PACHECO | O26: FRED PACHECO | P26: FRED PACHECO | Q26: FRED PACHECO | R26: FRED PACHECO | S26: FRED PACHECO | V26: 23 | W26: 23 | X26: 23 | Y26: 23 | Z26: 23 | AA26: 23 | AB26: 23 | AE26: =RAND() -> 0.30820465 | AF26: 23 | AG26: 23 | AH26: 23 | AI26: 23 | AJ26: 23 | AK26: 23 | AN26: 23 | AO26: FRED PACHECO
B27: 21 / 12 | C27: EDVALDO | D27: BRUNO REIS | E27: DENILSON | F27: PETRÚCIO | G27: GASPAR | H27: VÍTOR HUGO | I27: FRED PACHECO | N27: INÁCIO | O27: INÁCIO | P27: INÁCIO | V27: 24 | W27: 24 | X27: 24 | Y27: 24 | AB27: 24 | AE27: =RAND() -> 0.73756718 | AF27: 24 | AG27: 24 | AH27: 24 | AK27: 24 | AN27: 24 | AO27: DENILSON
B28: 24 / 12 | C28: INÁCIO | D28: DENILSON | E28: MOISÉS | F28: JACKSON | G28: PETRÚCIO | H28: MOSES | I28: JHOSEF | K28: ='Designações FDS ()'!J27 -> Lúcio Almeida | L28: ='Designações FDS ()'!K27 -> JOÃO CARLOS | N28: DENILSON | O28: DENILSON | P28: DENILSON | Q28: DENILSON | R28: DENILSON | S28: DENILSON | V28: 25 | W28: 25 | X28: 25 | Y28: 25 | AE28: =RAND() -> 0.81008899 | AF28: 25 | AG28: 25 | AH28: 25 | AN28: 25 | AO28: INÁCIO
B29: 28 / 12 | C29: DENILSON | D29: EDVALDO | E29: MAURICIO | F29: GASPAR | G29: DANIEL | H29: JOÃO CARLOS | I29: VÍTOR HUGO | N29: EDVALDO | O29: EDVALDO | P29: EDVALDO | V29: 26 | W29: 26 | X29: 26 | Y29: 26 | AE29: =RAND() -> 0.78126701 | AF29: 26 | AG29: 26 | AH29: 26 | AN29: 26 | AO29: EDVALDO
B30: 31 / 12 | C30: JACKSON | D30: FRED PACHECO | E30: TÉRCIO | F30: DAVID | G30: LEONEL | H30: JHOSEF | I30: MOSES | K30: ='Designações FDS ()'!J29 -> Waldines Lima | L30: ='Designações FDS ()'!K29 -> DENILSON | N30: PETRÚCIO | O30: PETRÚCIO | P30: PETRÚCIO | V30: 27 | W30: 27 | X30: 27 | Y30: 27 | AE30: =RAND() -> 0.59749132 | AF30: 27 | AG30: 27 | AH30: 27 | AN30: 27 | AO30: PETRÚCIO
N31: JACKSON | O31: JACKSON | P31: JACKSON | V31: 28 | W31: 28 | X31: 28 | Y31: 28 | AE31: =RAND() -> 0.29347154 | AF31: 28 | AG31: 28 | AH31: 28 | AN31: 28 | AO31: JACKSON
N32: MOSES | O32: MOSES | P32: MOSES | Q32: MOSES | R32: MOSES | V32: 29 | W32: 29 | X32: 29 | Y32: 29 | Z32: 29 | AA32: 29 | AE32: =RAND() -> 0.16834257 | AF32: 29 | AG32: 29 | AH32: 29 | AI32: 29 | AJ32: 29 | AN32: 29 | AO32: MOSES
O33: VÍTOR HUGO | P33: VÍTOR HUGO | Q33: VÍTOR HUGO | R33: VÍTOR HUGO | S33: VÍTOR HUGO | V33: 30 | X33: 30 | Y33: 30 | Z33: 30 | AA33: 30 | AB33: 30 | AE33: =RAND() -> 0.48428652 | AG33: 30 | AH33: 30 | AI33: 30 | AJ33: 30 | AK33: 30 | AN33: 30 | AO33: VÍTOR HUGO
O34: GASPAR | P34: GASPAR | V34: 31 | X34: 31 | Y34: 31 | AE34: =RAND() -> 0.082982756 | AG34: 31 | AH34: 31 | AN34: 31 | AO34: GASPAR
C35: TÉRCIO | D35: MOSES | E35: DENILSON | F35: JACKSON | G35: DANIEL | H35: JHOSEF | I35: JEAN LUCAS | O35: DANIEL | P35: DANIEL | Q35: DANIEL | R35: DANIEL | V35: 32 | X35: 32 | Y35: 32 | AE35: =RAND() -> 0.18686963 | AG35: 32 | AH35: 32 | AN35: 32 | AO35: DANIEL
O36: DAVID | V36: 33 | X36: 33 | AE36: =RAND() -> 0.79076768 | AG36: 33 | AN36: 33 | AO36: DAVID

Sheet Designações FDS ()
A2: DATA | B2: PRESIDENTE | C2: TEMA | D2: ORADOR / CONGREGAÇÃO | E2: LEITOR DE "A SENTINELA"
A3: 01 / 10 | B3: Almir Fernandes | E3: Bruno Reis | I3: 01 / 10 | J3: Almir Fernandes | K3: BRUNO REIS
A4: 08 / 10 | B4: Denis Pereira | E4: Jean Lucas
A5: 15 / 10 | B5: Bruno Reis | E5: Leonel Mangabeiras | I5: 08 / 10 | J5: Denis Pereira | K5: JEAN LUCAS
A6: 22 / 10 | B6: Jean Lucas | E6: Vítor Hugo
A7: 29 / 10 | B7: Vitor Medeiros | E7: Fred Pacheco | I7: 15 / 10 | J7: BRUNO REIS | K7: LEONEL
A8: 05 / 11 | B8: José Jhosef | E8: Denilson Reis
A9: 12 / 11 | B9: Fabrício Félix | E9: Bruno Reis | I9: 22 / 10 | J9: JEAN LUCAS | K9: VÍTOR HUGO
A10: 19 / 11 | B10: Maurício Bello | E10: João Carlos
A11: 26 / 11 | B11: Leonildo Jr. | E11: Jean Lucas | I11: 29 / 10 | J11: Vitor Medeiros | K11: FRED PACHECO
A12: 03 / 12 | B12: Adão Pereira | E12: Leonel Mangabeiras
A13: 10 / 12 | B13: Tércio Almeida | E13: Vítor Hugo | I13: 05 / 11 | J13: José Jhosef | K13: DENILSON
A14: 17 / 12 | B14: Eduardo Cato | E14: Fred Pacheco
A15: 24 / 12 | B15: Lúcio Almeida | E15: João Carlos | I15: 12 / 11 | J15: Fabrício Félix | K15: BRUNO REIS
A16: 31 / 12 | B16: Waldines Lima | E16: Denilson Reis
B17: Georgetown Silva | I17: 19 / 11 | J17: Maurício Bello | K17: JOÃO CARLOS
B18: Oliveiros Almeida
B19: Almir Fernandes | I19: 26 / 11 | J19: Leonildo Jr. | K19: JEAN LUCAS
B20: João Carlos
B21: Leonel Mangabeiras | I21: 03 / 12 | J21: Adão Pereira | K21: LEONEL
B22: Moisés Caetano
B23: Fabiano Correia | I23: 10 / 12 | J23: Tércio Almeida | K23: VÍTOR HUGO
B24: José Ailton
I25: 17 / 12 | J25: Eduardo Cato | K25: FRED PACHECO
I27: 24 / 12 | J27: Lúcio Almeida | K27: JOÃO CARLOS
I29: 31 / 12 | J29: Waldines Lima | K29: DENILSON

Sheet Aprovados pelo corpo
A1: INDICADORES | B1: MIC. VOL. | C1: PALCO | D1: ÁUDIO/VÍDEO | E1: LEITORES W | F1: PRESIDENTES
A4: Alisson Pinho | B4: Alisson Pinho | D4: Eduardo Lira | E4: Alisson Pinho | F4: Rafael Diniz
A5: Arnaldo Simões | B5: Arnaldo Simões | D5: Rafael Diniz | E5: Eduardo feitosa | F5: Herculano Alves
A6: Bruno Reis | B6: Bruno Reis | D6: Alisson Pinho | E6: Eduardo Lira | F6: Guilherme Freitas
A7: Eduardo feitosa | B7: Eduardo feitosa | D7: Kauã Silva | E7: Felipe Alcântara | F7: Felipe Alcantara
A8: Eduardo Lira | B8: Eduardo Lira | D8: Jailson | E8: Helton Lima | F8: Eduardo Lira
A9: Felipe Alcântara | B9: Felipe Alcântara | E9: Guilherme | F9: Helton Lima
A10: Helton Lima | B10: Luciano da Silva | E10: Bruno Reis | F10: Eduardo Moraes
A11: Luciano da Silva | B11: Helton Lima | E11: Kauã Silva | F11: Cristiano Binas
A12: Anderson | B12: Anderson | E12: Kleyton Silva | F12: John Carvalho
A13: Guilherme | B13: Rodrigo Muniz | E13: Otávio Teixeira | F13: George Nascimento
A14: Kauã Silva | B14: Antônio | E14: Rafael Bezerra | F14: Luiz Braga
A15: Kleyton Silva | B15: Guilherme | E15: Rafael Borel | F15: Rafael Borel
A16: Luiz Carneiro | B16: Kauã Silva | E16: Magno Miranda | F16: Adevaldo Morais
A17: Maurício Macário | B17: Kleyton Silva | E17: Rodrigo Muniz | F17: Eduardo Moraes
A18: Rodrigo Muniz | B18: Luíz Carneiro | E18: Luciano Pereira | F18: Waldson Vilar
A19: Otávio Teixeira | B19: Maurício Macário
A20: Philipe Lins | B20: Otávio Teixeira
A21: Rafael Bezerra | B21: Pedro Feitosa
A22: Rafael Borel | B22: Philipe Lins
A23: Severino Gomes | B23: Rafael Bezerra
A24: Magno Miranda | B24: Rafael Borel
A25: Antônio | B25: Severino Gomes
A26: João Victor | B26: Magno Miranda
B27: João Victor

Sheet Designações RVM
A1: Programação da Reunião de Meio de Semana
A3: 46022
A4: Leitura Semanal: Isaías 14-16 | G4: Presidente: | I4: Adevaldo Morais
H5: Ajudante: | I5: Jailson Ferreira
A7: 0.8125 | C7: Cântico 63 | H7: Dirigente Sala B: | I7: Waldson Vilar
A8: 0.81597222 | C8: Comentários iniciais (1 min) | H8: Oração inicial: | I8: Magno Miranda
A10: TESOUROS DA PALAVRA DE DEUS
A12: 0.81666667 | B12: • | C12: 1. Os inimigos do povo de Deus serão punidos (10 min) | I12: Felipe Alcântara
A13: 0.82361111 | B13: • | C13: 2. Encontre Joias Espirituais (10 min) | I13: Eduardo Morais
A14: 0.83055556 | B14: • | C14: 3. Leitura da Bíblia - Isaías 16:1-14 (4 min) | H14: Salão principal: | I14: Igor Simões
H15: Sala B: | I15: Luciano Silva
A17: FAÇA SEU MELHOR NO MINISTÉRIO
A19: 0.83333333 | B19: • | C19: 4. Iniciando conversas (3 min) | G19: Salão principal: | I19: Lamoniara Silva / Maria Luíza
B20: De casa em casa - Seja adaptável. | H20: Sala B: | I20: Nicole Kidman / Gleice Vieira
A22: 0.83611111 | B22: • | C22: 5. Cultivando o interesse (4 min) | G22: Salão principal: | I22: Eliz Muniz / Priscila Lins
B23: Testemunho público - Pense na pessoa interessada. | H23: Sala B: | I23: Emile Miranda / Maria Batista
A25: 0.83958333 | B25: • | C25: 6. Discurso (5 min) | G25: Salão principal: | I25: Rafael Borel
B26: Tema: O que é profecia? | H26: Sala B: | I26: Edvaldo Azevedo
A28: NOSSA VIDA CRISTÃ
A30: 0.84722222 | C30: Cântico 2
A32: 0.84861111 | B32: • | C32: 7. Necessidades locais (15 min) | I32: Josimar Júnior
A33: 0.85902778 | B33: • | C33: 8. Estudo bíblico de congregação. (30 min) | H33: Dirigente/Leitor: | I33: George e Kleyton Félix
A34: 0.87986111 | B34: • | C34: Comentários finais. (3 min)
A35: 0.88194444 | C35: Cântico 21 | H35: Oração final: | I35: Guilherme Alves
A141: TESOUROS DA PALAVRA DE DEUS
I142: Salão Principal
A143: 0.81666667 | C143: Como ter um namoro que resulte em uma boa decisão | I143: Eduardo Moraes
A144: 0.82361111 | C144: Encontre Joias Espirituais | I144: Felipe Alcântara
A145: 0.83055556 | C145: Leitura da Bíblia - Provérbios 20:1-15 | I145: Breno Lins
A147: FAÇA SEU MELHOR NO MINISTÉRIO
I148: Salão Principal
C149: Iniciando conversas | I149: Karla Coutinho / Eduarda Moraes
B150: DE CASA EM CASA
C152: Cultivando o interesse | I152: Ítala Lira / Larissa Caetano
B153: TESTEMUNHO PÚBLICO
C155: Explicando suas crenças | I155: Lamoniara Silva / Maria Luíza
B156: Tema: Será que os animais vão para o céu?
A158: NOSSA VIDA CRISTÃ
A159: 0.84444444 | C159: Cântico 78
I160: Designado
...

Sheet Designações Mecânicas
B1: DESIGNAÇÕES MECÂNICAS | J1: REUNIÃO FINAL DE SEM.
B3: DATA | C3: INDICADOR EXTERNO | D3: INDICADOR INTERNO | E3: MICROFONE VOLANTE | G3: PALCO | H3: ÁUDIO/VÍDEO | J3: PRESIDENTE | K3: LEITOR | N3: DATA | O3: TEMA | P3: ORADOR (CONGREGAÇÃO) | Q3: PRESIDENTE | R3: LEITOR DE "A SENTINELA"
B4: 45994 | C4: Rafael Diniz | D4: Luciano Silva | E4: Antônio | F4: Philipe Lins | H4: Alisson Pinho | N4: 45998 | O4: O que significa "andar com Deus"? | P4: Josimar Júnior (Candeias) | Q4: Eduardo Lira | R4: Rafael Borel
B5: 45998 | C5: Anderson | D5: Guilherme | E5: Arnaldo Simões | F5: João Victor | H5: Eduardo Lira
B6: 46001 | C6: Michel | D6: Rafael Borel | E6: Rodrigo Muniz | F6: Guilherme | H6: Jailson | N6: 46005 | O6: Ajamos sabiamente num mundo insensato. | P6: John Carvalho (Candeias) | Q6: Adevaldo Morais | R6: Helton Lima
B7: 46005 | C7: Luciano Silva | D7: Rodrigo Muniz | E7: Anderson | F7: Eduardo Feitosa | H7: Kauã Felix
B8: 46008 | C8: Magno Miranda | D8: Michel | E8: Eduardo Lira | F8: Rodrigo Muniz | H8: Rafael Diniz | N8: 46012 | O8: Como a sabedoria de Deus nos ajuda. | P8: Rafael Borel (Candeias) | Q8: Eduardo Moraes | R8: Alisson Pinho
B9: 46012 | C9: Rodrigo Muniz | D9: Magno Miranda | E9: Bruno Reis | F9: Guilherme | H9: Eduardo Lira
B10: 46015 | C10: Helton Lima | D10: Rodrigo Muniz | E10: Magno Miranda | F10: Luiz Carneiro | H10: Alisson Pinho | N10: 46019 | O10: Ande com Deus e receba bênçãos para sempre. | P10: Eduardo Moraes (Candeias) | Q10: Waldson Vilar | R10: Luciano Pereira
B11: 46019 | C11: Anderson | D11: Magno Miranda | E11: Pedro Feitosa | F11: Maurício Macário | H11: Jailson
B12: 46022 | C12: Severino Gomes | D12: Anderson | E12: Philipe Lins | F12: Rodrigo Muniz | H12: Kauã Felix
J14: =IF(Q14="","",Q14) | K14: =IF(R14="","",R14)
J15: =IF(Q15="","",Q15) | K15: =IF(R15="","",R15)
J16: =IF(Q16="","",Q16) | K16: =IF(R16="","",R16)
J17: =IF(Q17="","",Q17) | K17: =IF(R17="","",R17)
J18: =IF(Q18="","",Q18) | K18: =IF(R18="","",R18)
J19: =IF(Q19="","",Q19) | K19: =IF(R19="","",R19)
J20: =IF(Q20="","",Q20) | K20: =IF(R20="","",R20)
J21: =IF(Q21="","",Q21) | K21: =IF(R21="","",R21)
J22: =IF(Q22="","",Q22) | K22: =IF(R22="","",R22)
J23: =IF(Q23="","",Q23) | K23: =IF(R23="","",R23)
J24: =IF(Q24="","",Q24) | K24: =IF(R24="","",R24)
J25: =IF(Q25="","",Q25) | K25: =IF(R25="","",R25)
... J37: =IF(Q37="","",Q37) | K37: =IF(R37="","",R37)

Sheet Abertura Limpeza Campo
B1: Abertura do Salão do Reino | E1: Consideração de campo aos sábados no Salão às 8h45:
B2: REUNIÕES | C2: GRUPO RESPONSÁVEL | E2: DATA | F2: GRUPO RESPONSÁVEL
B3: 45841 | C3: NAIDE | E3: 45843 | F3: WALDINES
B4: 45844 | C4: SALÃO DO REINO | E4: 45850 | F4: NAIDE
B5: 45848 | C5: CARMINHA | E5: 45857 | F5: JARAGUÁ
B6: 45851 | C6: REGINALDO | E6: 45864 | F6: OLIVEIROS
B7: 45855 | C7: JARAGUÁ
B8: 45858 | C8: OLIVEIROS
B9: 45862 | C9: WALDINES
B10: 45865 | C10: NAIDE
B11: 45869 | C11: SALÃO DO REINO
B15: Limpeza
B16: REUNIÕES | C16: GRUPOS RESPONSÁVEIS
B17: 01/05 e 04/05 | C17: JARAGUÁ - CARMINHA
B18: 08/05 e 11/05 | C18: WALDINES - OLIVEIROS
B19: 15/05 e 18/05 | C19: REGINALDO - JARAGUÁ
B20: 22/05 e 25/05 | C20: WALDINES - NAIDE | E20: =COUNTIF(C19:C37,"NAIDE") -> 0
B21: 29/05 e 01/06 | C21: SALÃO DO REINO - OLIVEIROS
B22: 05/06 e 08/06 | C22: CARMINHA - REGINALDO
B23: 12/06 e 15/06 | C23: JARAGUÁ - WALDINES
B24: 19/06 e 22/06 | C24: NAIDE - SALÃO DO REINO
B25: 26/06 e 29/06 | C25: OLIVEIROS - CARMINHA
B26: 45963 | C26: ESMERALDA - TOPÁZIO
B27: 45966
B28: 45970
B29: 45994 | C29: JACINTO - PÉROLA
B30: 45998 | C30: JACINTO - PÉROLA
B31: 46001 | C31: AMETISTA - CRISÓLITO
B32: 46005 | C32: AMETISTA - CRISÓLITO
B33: 46008 | C33: ESMERALDA - TOPÁZIO
B34: 46012 | C34: ESMERALDA - TOPÁZIO
B35: 46015 | C35: JACINTO - PÉROLA
B36: 46019 | C36: JACINTO - PÉROLA
B37: 46022 | C37: AMETISTA - CRISÓLITO

Sheet Aprovados 2024
A1: INDICADORES | B1: MIC. VOL. | C1: PALCO | D1: MIDIA | E1: LEITORES | F1: PRESIDENTES | I1: INDICADORES | J1: MIC. VOL. | K1: PALCO | L1: MIDIA | M1: ANFITRIÕES | N1: LEITORES | O1: PRESIDENTES | R1: INDICADORES | S1: MIC. VOL. | T1: PALCO | U1: MIDIA | V1: ANFITRIÕES | W1: LEITORES | X1: PRESIDENTES
AB3: INDICADORES SEM MÍDIA
A4: ALAN | B4: ALAN | C4: ALAN | D4: BRUNO REIS | E4: BRUNO REIS | F4: CRISTIANO BINAS | H4: 1 | O4: 1 | Q4: =RAND() -> 0.35605747 | X4: 1 | Z4: 1 | AA4: AILTON | AB4: ALAN
A5: BRUNO REIS | B5: ARTHUR GABRIEL | C5: ARTHUR GABRIEL | D5: DANIEL | E5: DENILSON REIS | F5: ARNALDO | H5: 2 | O5: 2 | Q5: =RAND() -> 0.69416396 | X5: 2 | Z5: 2 | AA5: DENIS | AB5: EDVALDO MARTINS
A6: DENILSON REIS | B6: DANIEL | C6: DANIEL | D6: DEYVID ALVES | E6: ISRAEL FÉLIX | F6: BRUNO REIS | H6: 3 | O6: 3 | Q6: =RAND() -> 0.8035402 | X6: 3 | Z6: 3 | AA6: VITOR MEDEIROS | AB6: GASPAR BELLO
A7: DIRCEU | B7: DENILSON REIS | C7: DEYVID ALVES | D7: GASPAR BELLO | E7: JHOSEF SILVA | F7: DENIS PEREIRA | H7: 4 | O7: 4 | Q7: =RAND() -> 0.37058042 | X7: 4 | Z7: 4 | AA7: FABRÍCIO | AB7: INÁCIO SILVA
A8: EDVALDO MARTINS | B8: DEYVID ALVES | C8: DIRCEU | D8: JHOSEF SILVA | E8: JOÃO CAVALCANTE | F8: FABIANO CORREIA | H8: 5 | O8: 5 | Q8: =RAND() -> 0.98083308 | X8: 5 | Z8: 5 | AA8: LEONILDO | AB8: ISRAEL F.
A9: FRANCISCO | B9: DIRCEU | C9: EDVALDO MARTINS | D9: JOÃO CAVALCANTE | E9: LEONEL MANGAB. | F9: FABRÍCIO FÉLIX | H9: 6 | O9: 6 | Q9: =RAND() -> 0.18985556 | X9: 6 | Z9: 6 | AA9: ADÃO | AB9: JACKSON ARAÚJO
A10: INÁCIO SILVA | B10: EDVALDO MARTINS | C10: FRANCISCO | D10: MURILO | E10: PAULO CAMPOS | F10: GEORGETOWN | H10: 7 | O10: 7 | Q10: =RAND() -> 0.25447052 | X10: 7 | Z10: 7 | AA10: EDUARDO | AB10: LEONEL MANGAB.
A11: ISRAEL FÉLIX | B11: FRANCISCO | C11: GASPAR BELLO | E11: TÉRCIO ALMEIDA | F11: JHOSEF SILVA | H11: 8 | O11: 8 | Q11: =RAND() -> 0.20919801 | X11: 8 | Z11: 8 | AA11: FABIANO | AB11: MOISÉS CAETANO
A12: JAIR | B12: GASPAR BELLO | C12: INÁCIO SILVA | F12: JOÃO CAVALCANTE | H12: 9 | O12: 9 | Q12: =RAND() -> 0.4245025 | X12: 9 | Z12: 9 | AA12: LÚCIO | AB12: PAULO CAMPOS
A13: JACKSON ARAÚJO | B13: GEORGETOWN FH | C13: ISRAEL FÉLIX | F13: JOSÉ AILTON | H13: 10 | O13: 10 | Q13: =RAND() -> 0.26889291 | X13: 10 | Z13: 10 | AA13: WALDINES | AB13: PETRÚCIO
A14: JHOSEF SILVA | B14: GUILHERME | C14: JACKSON ARAÚJO | F14: LEONEL MANGAB. | H14: 11 | O14: 11 | Q14: =RAND() -> 0.33404283 | X14: 11 | Z14: 11 | AA14: GEORGETOWN | AB14: TÉRCIO ALMEIDA
A15: JOÃO CAVALCANTE | B15: INÁCIO SILVA | C15: JAIR | F15: LEONILDO JR. | H15: 12 | O15: 12 | Q15: =RAND() -> 0.64162566 | X15: 12 | Z15: 12 | AA15: OLIVEIROS
A16: LEONEL MANGAB. | B16: ISRAEL FÉLIX | C16: LEONEL MANGAB. | F16: LÚCIO ALMEIDA | H16: 13 | O16: 13 | Q16: =RAND() -> 0.76472971 | X16: 13 | Z16: 13 | AA16: ALMIR
A17: MARCOS LIRA | B17: JACKSON ARAÚJO | C17: MARCOS LIRA | F17: MAURÍCIO BELLO | H17: 14 | I17: 14 | J17: 14 | K17: 14 | L17: 14 | M17: 14 | N17: 14 | O17: 14 | Q17: =RAND() -> 0.50022557 | R17: 14 | S17: 14 | T17: 14 | U17: 14 | V17: 14 | W17: 14 | X17: 14 | Z17: 14 | AA17: JOÃO CARLOS
A18: MOISÉS CAETANO | B18: JAIR | C18: MOISÉS CAETANO | F18: MOISÉS CAETANO | H18: 15 | I18: 15 | J18: 15 | K18: 15 | L18: 15 | M18: 15 | N18: 15 | O18: 15 | Q18: =RAND() -> 0.48724175 | R18: 15 | S18: 15 | T18: 15 | U18: 15 | V18: 15 | W18: 15 | X18: 15 | Z18: 15 | AA18: BRUNO REIS
A19: PAULO CAMPOS | B19: LEONEL MANGAB. | C19: MURILO | F19: OLIVEIROS ALMEIDA | H19: 16 | I19: 16 | J19: 16 | K19: 16 | L19: 16 | M19: 16 | N19: 16 | O19: 16 | Q19: =RAND() -> 0.13257429 | R19: 16 | S19: 16 | T19: 16 | U19: 16 | V19: 16 | W19: 16 | X19: 16 | Z19: 16 | AA19: JEAN LUCAS
A20: PETRÚCIO | B20: MARCOS LIRA | C20: PAULO CAMPOS | F20: PEDRO | H20: 17 | I20: 17 | J20: 17 | K20: 17 | N20: 17 | O20: 17 | Q20: =RAND() -> 0.32071076 | R20: 17 | S20: 17 | T20: 17 | W20: 17 | X20: 17 | Z20: 17 | AA20: LEONEL
A21: TÉRCIO ALMEIDA | B21: MIGUEL LEVI | C21: PETRÚCIO | F21: TÉRCIO ALMEIDA | H21: 18 | I21: 18 | J21: 18 | K21: 18 | L21: 18 | M21: 18 | O21: 18 | Q21: =RAND() -> 0.33298679 | R21: 18 | S21: 18 | T21: 18 | U21: 18 | V21: 18 | X21: 18 | Z21: 18 | AA21: JHOSEF
A22: ZARMÂNIO | B22: MOISÉS CAETANO | C22: RICHARLISON | F22: VITOR MEDEIROS | H22: 19 | I22: 19 | J22: 19 | K22: 19 | O22: 19 | Q22: =RAND() -> 0.15390395 | R22: 19 | S22: 19 | T22: 19 | X22: 19 | Z22: 19 | AA22: MOISÉS
B23: MURILO | C23: TÉRCIO ALMEIDA | F23: WALDINES LIMA | H23: 20 | I23: 20 | J23: 20 | K23: 20 | O23: 20 | Q23: =RAND() -> 0.85839209 | R23: 20 | S23: 20 | T23: 20 | X23: 20 | Z23: 20 | AA23: MAURÍCIO
B24: PAULO CAMPOS | C24: WEYNERT | F24: ZARMÂNIO | H24: 21 | I24: 21 | J24: 21 | K24: 21 | O24: 21 | Q24: =RAND() -> 0.33209323 | R24: 21 | S24: 21 | T24: 21 | X24: 21 | Z24: 21 | AA24: TÉRCIO
B25: PETRÚCIO | C25: ZARMÂNIO | H25: 22 | I25: 22 | J25: 22 | K25: 22 | Q25: =RAND() -> 0.77419184 | R25: 22 | S25: 22 | T25: 22 | Z25: 22 | AA25: ISRAEL F.
B26: RICHARLISON | H26: 23 | I26: 23 | J26: 23 | K26: 23 | L26: 23 | M26: 23 | N26: 23 | Q26: =RAND() -> 0.74916527 | R26: 23 | S26: 23 | T26: 23 | U26: 23 | V26: 23 | W26: 23 | Z26: 23 | AA26: FRED PACHECO
B27: TÉRCIO ALMEIDA | H27: 24 | I27: 24 | J27: 24 | K27: 24 | N27: 24 | Q27: =RAND() -> 0.70121766 | R27: 24 | S27: 24 | T27: 24 | W27: 24 | Z27: 24 | AA27: DENILSON
B28: WEYNERT | H28: 25 | I28: 25 | J28: 25 | K28: 25 | Q28: =RAND() -> 0.080248572 | R28: 25 | S28: 25 | T28: 25 | Z28: 25 | AA28: INÁCIO
B29: ZARMÂNIO | H29: 26 | I29: 26 | J29: 26 | K29: 26 | Q29: =RAND() -> 0.55619615 | R29: 26 | S29: 26 | T29: 26 | Z29: 26 | AA29: EDVALDO
H30: 27 | I30: 27 | J30: 27 | K30: 27 | Q30: =RAND() -> 0.47955805 | R30: 27 | S30: 27 | T30: 27 | Z30: 27 | AA30: PETRÚCIO
H31: 28 | I31: 28 | J31: 28 | K31: 28 | Q31: =RAND() -> 0.82701658 | R31: 28 | S31: 28 | T31: 28 | Z31: 28 | AA31: JACKSON
H32: 29 | I32: 29 | J32: 29 | K32: 29 | L32: 29 | M32: 29 | Q32: =RAND() -> 0.61093772 | R32: 29 | S32: 29 | T32: 29 | U32: 29 | V32: 29 | Z32: 29 | AA32: MOSES
H33: 30 | J33: 30 | K33: 30 | L33: 30 | M33: 30 | N33: 30 | Q33: =RAND() -> 0.67216456 | S33: 30 | T33: 30 | U33: 30 | V33: 30 | W33: 30 | Z33: 30 | AA33: VÍTOR HUGO
H34: 31 | J34: 31 | K34: 31 | Q34: =RAND() -> 0.20882515 | S34: 31 | T34: 31 | Z34: 31 | AA34: GASPAR
H35: 32 | J35: 32 | K35: 32 | Q35: =RAND() -> 0.52917994 | S35: 32 | T35: 32 | Z35: 32 | AA35: DANIEL
H36: 33 | J36: 33 | Q36: =RAND() -> 0.87362164 | S36: 33 | Z36: 33 | AA36: DAVID

Sheet Designações FDS
B3: DATA | C3: PRESIDENTE | D3: TEMA | E3: ORADOR / CONGREGAÇÃO | F3: LEITOR DE "A SENTINELA"
B5: 04/05 | C5: DENIS PEREIRA | F5: TÉRCIO ALMEIDA
B7: 11/05 | C7: FABIANO CORREIA | F7: LEONEL MANGAB.
B9: 18/05 | C9: FABRÍCIO FÉLIX | F9: PAULO CAMPOS
B11: 25/05 | C11: GEORGETOWN | F11: BRUNO REIS

Sheet Grupos
A1: Grupo 1 - Salão do Reino | C1: Grupo 2 - Oliveiros | E1: Grupo 3 - Waldines | G1: Grupo 4 - Naide
A2: Av. Brasil, 98, Poço | C2: Rua Castro Alves, 282, Poço | E2: Rua Santa Sofia, 146, Ponta da Terra | G2: R. Lafaiete Pacheco, 3572, Ponta da Terra
A3: SG: Arnaldo (82)99993-5036 Ajudante: Georgetown (82)99986-1118 | C3: SG: Lúcio (82)99905-7618 Ajudante: Oliveiros (82)98863-9356, Bruno (82)99612-4674 e Tércio (82)99921-3337 | E3: SG: Maurício (82)98219-5763 Ajudante: João Carlos (82)99910-8662 e Israel (82)98846-0218 | G3: SG: Fabiano (82)99823-4623 Ajudante: Fabrício (82)99134-4845 e Denilson (82)98124-6801
A6: 1 | B6: Adriana de Melo Santiago (PNB) | C6: 1 | D6: Antonieta Nobre dos Santos | E6: 1 | F6: Alan Guilherme Barbosa (PNB) | G6: 1 | H6: Agrícia Mendes dos Santos
A7: 2 | B7: Alan Viana | C7: 2 | D7: Bruno Reis | E7: 2 | F7: Alane Kelle Barbosa da Silva | G7: 2 | H7: Denilson Reis
A8: 3 | B8: Aldalice Conceição Ramos | C8: 3 | D8: Elisabete Bezerra Almeida | E8: 3 | F8: Cleonice Francelino Martins | G8: 3 | H8: Elangela
A9: 4 | B9: Arnaldo Gomes | C9: 4 | D9: Gedalva Nobre dos Santos | E9: 4 | F9: Eriene da Silva Santos | G9: 4 | H9: Fabrício Félix
A10: 5 | B10: Claudiceia Pereira | C10: 5 | D10: Isa Keylla Amaral | E10: 5 | F10: Francisco José Martins Almeida | G10: 5 | H10: Giovanna Dias da Silva (PNB)
A11: 6 | B11: Cristiano Marques Binas | C11: 6 | D11: Jamerson Daniel | E11: 6 | F11: Gaspar Bello | G11: 6 | H11: Ivilis Santos Silvestre
A12: 7 | B12: Dirceu Antunes | C12: 7 | D12: Jeine Walkíria Almeida | E12: 7 | F12: Genilda Francelino M. S. Almeida | G12: 7 | H12: Janaina da Silva
A13: 8 | B13: Edinete Lima de Oliveira | C13: 8 | D13: Juraci de Souza Silva | E13: 8 | F13: Israel Félix | G13: 8 | H13: Joana D'arc da Silva
A14: 9 | B14: Emmily Morais | C14: 9 | D14: Kleycianny Reis | E14: 9 | F14: João Carlos Cavalcante | G14: 9 | H14: João Júlio Mendes de Barros
A15: 10 | B15: Georgetown da Silva | C15: 10 | D15: Lúcio Bezerra de Almeida | E15: 10 | F15: Maria Clara Barbosa de Lima | G15: 10 | H15: José Petrúcio da Anunciação
A16: 11 | B16: Georgetown Filho (Georginho) | C16: 11 | D16: Maria de Lourdes de Oliveira Amaral | E16: 11 | F16: Maria das Dores | G16: 11 | H16: Josilene do Nascimento (Rosa)
A17: 12 | B17: Karla Pordeus de Oliveira | C17: 12 | D17: Maria Luiza de Almeida | E17: 12 | F17: Mariano Francelino | G17: 12 | H17: Lorena Mendes Santos
... A20: 15 | B20: Mary Celi Santos Oliveira | C20: 15 | D20: Tércio Bezerra Almeida | E20: 15 | F20: Mauricio Bello | G20: 15 | H20: Maria Aparecida de Amorim Guedes
A21: 16 | B21: Rodrigo Araújo | C21: 16 | E21: 16 | F21: Patrícia Bello | G21: 16 | H21: Melissa Andressa Correa
A22: 17 | B22: Solange Azevedo | C22: 17 | E22: 17 | F22: Thalia Omena Cavalcante | G22: 17 | H22: Naide Maria da Silva
A23: 18 | B23: Tereza Cristina Gomes | C23: 18 | E23: 18 | F23: Waldines José de Lima | G23: 18 | H23: Renata de Oliveira Couto
A24: 19 | B24: Wellen Albuquerque da Paz | C24: 19 | E24: 19 | G24: 19 | H24: Sandra Reis
A25: 20 | B25: Wilma Monteiro | C25: 20 | E25: 20 | G25: 20 | H25: Shirley de Amorim Guedes
A26: 21 | C26: 21 | E26: 21 | G26: 21 | H26: Sophia Dias da Silva (PNB)
A27: 22 | C27: 22 | E27: 22 | G27: 22 | H27: Vitória Nunes da Silva
A28: Grupo 5 - Farol | C28: Grupo 6 - Carminha | E28: Grupo 7 - Reginaldo | G28: Grupo 8 - Jaraguá
A29: Av. Gov. Afrânio Lages, 149, Farol | C29: Rua José Correia Filho, 771, Poço | E29: Rua Diegues Junior Nº 10, Reginaldo, Poço | G29: Rua Santa Ana, 100 Poço
A30: SG: Leonildo (82)99644-2457 Ajudante: Moisés (82)98847-0722 e Zarmanio (82)99316-3518 | C30: SG: Almir (82)98190-1322 Ajudante: Carlos Vitor (82)99672-6097 e Leonel (82)98205-4908 | E30: SG: Ailton (82)99411-0742 Ajudante: Joseph (82)98753-1100 e Jackson (82)99927-3560 | G30: SG: Pedro (82)98112-1130 Ajudante: Denes (82)99990-8419 e
A33: 1 | B33: Ana Julia Caetano | C33: 1 | D33: Almir Fernandes da Cruz | E33: 1 | F33: Deyvid Martins Alves | G33: 1 | H33: Angeli Carvalho
A34: 2 | B34: Andréa de Carvalho | C34: 2 | D34: Carlos Vitor Medeiros | E34: 2 | F34: Edvaldo Francelino Martins | G34: 2 | H34: Arthur Gabriel
A35: 3 | B35: Anny Beatriz Machado Lopes | C35: 3 | D35: João José do Nascimento Filho | E35: 3 | F35: Elaine Lessa Silva | G35: 3 | H35: Cícero Bezerra
A36: 4 | B36: Gleibe Santana Marques | C36: 4 | D36: Juliana Lopes Fernandes | E36: 4 | F36: Eliane Lessa Martins | G36: 4 | H36: Denes Pereira dos Santos
A37: 5 | B37: Jair Marques | C37: 5 | D37: Leilany Medeiros | E37: 5 | F37: Francisca Binas | G37: 5 | H37: Eurides Freitas Merquiades
A38: 6 | B38: Laura Santana Marques | C38: 6 | D38: Leonel Mangabeira | E38: 6 | F38: Francisco Pereira | G38: 6 | H38: Inácio Manoel da Silva Filho
A39: 7 | B39: Leonildo de Carvalho Jr | C39: 7 | D39: Maria Claudia Almeida | E39: 7 | F39: Jackson Araujo do Nascimento | G39: 7 | H39: Jaqueline Bezerra
A40: 8 | B40: Maria José de Vasconcelos (Zeza) | C40: 8 | D40: Maria do Carmo Santos de Almeida | E40: 8 | F40: José Ailton Santana Alves | G40: 8 | H40: José Marcos Lira
A41: 9 | B41: Moisés Caetano | C41: 9 | D41: Marli Santos de Almeida | E41: 9 | F41: José Cristian Joseph | G41: 9 | H41: Miguel Levi
A42: 10 | B42: Paulo Campos | C42: 10 | D42: Marta Eliane de Almeida | E42: 10 | F42: Maria Madalena Rocha Silva | G42: 10 | H42: Murilo Lira
A43: 11 | B43: Rafaela Campos | C43: 11 | D43: Maura Mangabeiras de Araújo | E43: 11 | F43: Maria Quitéria da Silva Alves | G43: 11 | H43: Paulina da Silva Lopes
A44: 12 | B44: Zarmânio Ferreira Cavalcante | C44: 12 | D44: Selma Santos de Almeida | E44: 12 | F44: Maria Rosimeire C. (Rosa - Edson) | G44: 12 | H44: Pedro Oliveira
A45: 13 | C45: 13 | D45: Vânia Sandra Santos do Nascimento | E45: 13 | F45: Maria Sebastiana Bertoldo Araújo | G45: 13
A46: 14 | C46: 14 | E46: 14 | F46: Richarlison Anjo de Lima | G46: 14
...

Sheet Limpeza
B2: REUNIÕES | C2: GRUPOS RESPONSÁVEIS
B3: 01 e 05 / 10 | C3: Farol
B4: 08 e 12 / 10 | C4: Salão do Reino
B5: 15 e 19 / 10 | C5: Petrúcio
B6: 22 e 26 / 10 | C6: Oliveiros
B7: 29/10 e 02/11 | C7: Carminha
B9: 05 e 09 / 11 | C9: Farol - Salão do Reino
B10: 12 e 16 / 11 | C10: Reginaldo - Jaraguá
B11: 19 e 23 / 11 | C11: Waldines - Petrúcio
B12: 26 e 30 / 11 | C12: Oliveiros - Carminha
B14: 31/12 e 03/01 | C14: Farol - Salão do Reino
B15: 06 e 10 / 01 | C15: Reginaldo - Jaraguá
... B22: 25/12 e 28/12 | C22: CARMINHA - REGINALDO

Sheet Saídas Campo
C3: MANHÃ | D3: TARDE | E3: NOITE
B4: SEGUNDA-FEIRA | C4: Não há consideração para o serviço de campo. | D4: Não há consideração para o serviço de campo. | E4: Não há consideração para o serviço de campo.
B8: TERÇA-FEIRA | C8: Saída: Salão do Reino | D8: Não há consideração para o serviço de campo. | E8: Saída: Salão do Reino
C9: Horário: 08:15 | E9: Horário: 19:00
C10: Todos os Grupos | E10: Todos os Grupos
C11: Dirigente(s): Adevaldo / Edvaldo | E11: Dirigente(s): Magno / Arnaldo
B12: QUARTA-FEIRA | C12: Saída: Salão do Reino | D12: Não há consideração para o serviço de campo. | E12: Não há consideração para o serviço de campo.
C13: Horário: 08:15
C14: Todos os Grupos
C15: Dirigente(s): Edvaldo
B16: QUINTA-FEIRA | C16: Saída: Salão do Reino (Arranjo de cartas) | E16: Não há consideração para o serviço de campo.
C17: Horário: 08:15 - 17:00
C18: Todos os Grupos
C19: Dirigente(s): Edvaldo / Rafael Diniz
B20: SEXTA-FEIRA | C20: Não há consideração para o serviço de campo. | D20: Não há consideração para o serviço de campo. | E20: Não há consideração para o serviço de campo.
B24: SÁBADO | C24: Saída: Salão do Reino | D24: Saída: Salão do Reino | E24: Não há consideração para o serviço de campo.
C25: Horário: 08:30 | D25: Horário: 15:30
C26: Todos os Grupos | D26: Todos os Grupos
C27: Dirigente(s): Escala de revezamento | D27: Dirigente(s): Escala de revezamento
B28: DOMINGO | C28: Saída: Respectivos Grupos | D28: Não há consideração para o serviço de campo. | E28: Não há consideração para o serviço de campo.
C29: Horário: 08:30
C30: Dirigente(s): SG's e Ajudantes

Sheet Planilha1
B1: REGINALDO | C1: JARAGUÁ | D1: WALDINES | E1: NAIDE | F1: SALÃO DO REINO | G1: OLIVEIROS | H1: CARMINHA | J1: REGINALDO | K1: JARAGUÁ
A2: REGINALDO | C2: =_xlfn.CONCAT($A$2," E ", C1) -> REGINALDO E JARAGUÁ | D2: =_xlfn.CONCAT($A$2," E ", D1) -> REGINALDO E WALDINES | E2: =_xlfn.CONCAT($A$2," E ", E1) -> REGINALDO E NAIDE | F2: =_xlfn.CONCAT($A$2," E ", F1) -> REGINALDO E SALÃO DO REINO | G2: =_xlfn.CONCAT($A$2," E ", G1) -> REGINALDO E OLIVEIROS | H2: =_xlfn.CONCAT($A$2," E ", H1) -> REGINALDO E CARMINHA | J2: WALDINES | K2: NAIDE
A3: JARAGUÁ | D3: =_xlfn.CONCAT($A$3," E ", D1) -> JARAGUÁ E WALDINES | E3: =_xlfn.CONCAT($A$3," E ", E1) -> JARAGUÁ E NAIDE | F3: =_xlfn.CONCAT($A$3," E ", F1) -> JARAGUÁ E SALÃO DO REINO | G3: =_xlfn.CONCAT($A$3," E ", G1) -> JARAGUÁ E OLIVEIROS | H3: =_xlfn.CONCAT($A$3," E ", H1) -> JARAGUÁ E CARMINHA | J3: SALÃO DO REINO - | K3: OLIVEIROS
A4: WALDINES | E4: =_xlfn.CONCAT($A$4," E ", E1) -> WALDINES E NAIDE | F4: =_xlfn.CONCAT($A$4," E ", F1) -> WALDINES E SALÃO DO REINO | G4: =_xlfn.CONCAT($A$4," E ", G1) -> WALDINES E OLIVEIROS | H4: =_xlfn.CONCAT($A$4," E ", H1) -> WALDINES E CARMINHA | J4: CARMINHA | K4: REGINALDO
A5: NAIDE | F5: =_xlfn.CONCAT($A$5," E ", F1) -> NAIDE E SALÃO DO REINO | G5: =_xlfn.CONCAT($A$5," E ", G1) -> NAIDE E OLIVEIROS | H5: =_xlfn.CONCAT($A$5," E ", H1) -> NAIDE E CARMINHA | J5: JARAGUÁ | K5: WALDINES
A6: SALÃO DO REINO | G6: =_xlfn.CONCAT($A$6," E ", G1) -> SALÃO DO REINO E OLIVEIROS | H6: =_xlfn.CONCAT($A$6," E ", H1) -> SALÃO DO REINO E CARMINHA | J6: NAIDE | K6: SALÃO DO REINO -
A7: OLIVEIROS | H7: =_xlfn.CONCAT($A$7," E ", H1) -> OLIVEIROS E CARMINHA | J7: OLIVEIROS | K7: CARMINHA
A8: CARMINHA
A10: REGINALDO - JARAGUÁ
A11: WALDINES - NAIDE | F11: DATA | H11: GRUPO RESPONSÁVEL
A12: SALÃO DO REINO - OLIVEIROS | F12: MAIO | G12: 45781 | H12: José Ailton Santana Alves
A13: CARMINHA - REGINALDO | D13: Elaine Lessa Silva | G13: 45788 | H13: João Carlos Martins
A14: JARAGUÁ - WALDINES | D14: Eliane Lessa Martins | E14: Jackson Araujo do Nascimento | G14: 45795 | H14: José Ailton Santana Alves
A15: NAIDE - SALÃO DO REINO | D15: Francisca Binas | G15: 45802 | H15: Edvaldo Francelino Martins
A16: OLIVEIROS - CARMINHA | F16: JUNHO | G16: 45809 | H16: José Ailton Santana Alves
A17: REGINALDO - WALDINES | G17: 45816 | H17: Francisco Pereira
A18: JARAGUÁ - NAIDE | G18: 45823 | H18: José Ailton Santana Alves
A19: SALÃO DO REINO - CARMINHA | G19: 45830 | H19: Deyvid Martins Alves
A20: OLIVEIROS - REGINALDO | D20: Maria Quitéria da Silva Alves | G20: 45837 | H20: José Ailton Santana Alves
A21: WALDINES - CARMINHA | D21: Maria Rosimeire C. (Rosa - Edson)
A22: NAIDE - OLIVEIROS | D22: Maria Sebastiana Bertoldo Araújo
A23: SALÃO DO REINO - JARAGUÁ | D23: Richarlisson AnJo de Lima
A24: REGINALDO - NAIDE | D24: Thainá Anjo da Silva Farias
A25: JARAGUÁ - OLIVEIROS | D25: Thalia Omena Cavalcante
A26: WALDINES - SALÃO DO REINO | D26: Weynert Soares Penha
A27: NAIDE - CARMINHA
A28: REGINALDO - SALÃO DO REINO
A29: JARAGUÁ - CARMINHA
A30: WALDINES - OLIVEIROS

Sheet Grupos (2)
A1: Grupo 1 - Salão do Reino | C1: Grupo 2 - Oliveiros | E1: Grupo 3 - Waldines | G1: Grupo 4 - Petrúcio
A2: Av. Brasil, 98, Poço | C2: Rua Castro Alves, 282, Poço | E2: Rua Santa Sofia, 146, P. da Terra | G2: R. Lafaiete Pacheco, 3572, P. da Terra
A3: SG: Arnaldo (82)99993-5036 | C3: SG: Lúcio (82)99905-7618 | E3: SG: Maurício (82)98219-5763 | G3: SG: Fabiano (82)99823-4623
A4: Ajudante: Georgetown (82)99986-1118 | C4: Ajudante: Oliveiros (82)98863-9356, Bruno (82)99612-4674 e Tércio (82)99921-3337 | E4: Ajudante: João Carlos (82)9910-8662 | G4: Ajudante: Fabrício (82)99134-4845 e Denilson (82)98124-6801
A6: 1 | B6: Adriana de Melo Santiago (PNB) | C6: 1 | D6: Antonieta Nobre dos Santos | E6: 1 | F6: Alan Guilherme Barbosa (PNB) | G6: 1 | H6: Agrícia Mendes dos Santos
A7: 2 | B7: Alan Viana | C7: 2 | D7: Bruno Reis | E7: 2 | F7: Alane Kelle Barbosa da Silva | G7: 2 | H7: Denilson Reis
A8: 3 | B8: Aldalice Conceição Ramos | C8: 3 | D8: Elisabete Bezerra Almeida | E8: 3 | F8: Cleonice Francelino Martins | G8: 3 | H8: Elangela Gomes Mendes
A9: 4 | B9: Arnaldo Gomes | C9: 4 | D9: Gedalva Nobre dos Santos | E9: 4 | F9: Eriene da Silva Santos | G9: 4 | H9: Fabrício Félix
A10: 5 | B10: Claudiceia Pereira | C10: 5 | D10: Isa Keylla Amaral | E10: 5 | F10: Francisco José Martins Almeida | G10: 5 | H10: Giovanna Dias da Silva (PNB)
A11: 6 | B11: Cristiano Marques Binas | C11: 6 | D11: Jamerson Daniel | E11: 6 | F11: Gaspar Bello | G11: 6 | H11: Ivilis Santos Silvestre
A12: 7 | B12: Dirceu Antunes | C12: 7 | D12: Jeine Walkíria Almeida | E12: 7 | F12: Genilda Francelino M. S. Almeida | G12: 7 | H12: Janaina da Silva
A13: 8 | B13: Edinete Lima de Oliveira | C13: 8 | D13: Juraci de Souza Silva | E13: 8 | F13: Israel Félix | G13: 8 | H13: Joana D'arc da Silva
A14: 9 | B14: Emmily Morais | C14: 9 | D14: Kleycianny Reis | E14: 9 | F14: João Carlos Martins | G14: 9 | H14: João Júlio Mendes de Barros
A15: 10 | B15: Georgetown da Silva | C15: 10 | D15: Lúcio Bezerra de Almeida | E15: 10 | F15: Maria Clara Barbosa de Lima | G15: 10 | H15: José Petrúcio da Anunciação
A16: 11 | B16: Georgetown Filho (Georginho) | C16: 11 | D16: Maria de Lourdes de O. Amaral | E16: 11 | F16: Maria das Dores | G16: 11 | H16: Josilene do Nascimento (Rosa)
A17: 12 | B17: Karla Pordeus de Oliveira | C17: 12 | D17: Maria Luiza de Almeida | E17: 12 | F17: Marilucia Silva de Deus | G17: 12 | H17: Lorena Mendes Santos
... A20: 15 | B20: Mary Celi Santos Oliveira | C20: 15 | D20: Tércio Bezerra Almeida | E20: 15 | F20: Marta Maria Silva | G20: 15 | H20: Maria Aparecida de A. Guedes
A21: 16 | B21: Solange Azevedo | C21: 16 | E21: 16 | F21: Mauricio Bello | G21: 16 | H21: Melissa Andressa Correa
A22: 17 | B22: Tereza Cristina Gomes | C22: 17 | E22: 17 | F22: Patrícia Bello | G22: 17 | H22: Naide Maria da Silva
A23: 18 | B23: Wellen Albuquerque da Paz | C23: 18 | E23: 18 | F23: Thalia Omena | G23: 18 | H23: Renata de Oliveira Couto
A24: 19 | B24: Wilma Monteiro | C24: 19 | E24: 19 | F24: Waldines José de Lima | G24: 19 | H24: Sandra Reis
A25: 20 | C25: 20 | E25: 20 | G25: 20 | H25: Shirley de Amorim Guedes
G26: 21 | H26: Sophia Dias da Silva (PNB)
A27: Grupo 5 - Farol | C27: Grupo 6 - Carminha | E27: Grupo 7 - Reginaldo | G27: Grupo 8 - Jaraguá
A28: Av. Gov. Afrânio Lages, 149, Farol | C28: Rua José Correia Filho, 771, Poço | E28: Rua Diegues Junior Nº 10, Reginaldo, Poço | G28: Rua Santa Ana, 100, Poço
A29: SG: Leonildo (82)99644-2457 | C29: SG: Almir (82)98190-1322 | E29: SG: Ailton (82)99411-0742 | G29: SG: Pedro (82)98112-1130
A30: Ajudante: Moisés (98847-0722) e Zarmanio (82)99316-3518 | C30: Ajudante: Vitor (82)99672-6097 e Leonel (82)98205-4908 | E30: Ajudante: Christian Gomes | G30: Ajudante: Denes (82)99990-8419 e Joseph (82)98753-1100
A32: 1 | B32: Ana Julia Caetano | C32: 1 | D32: Almir Fernandes da Cruz | E32: 1 | F32: Andréa Maria Morais Gonçalves | G32: 1 | H32: Angeli Carvalho
A33: 2 | B33: Andréa de Carvalho | C33: 2 | D33: Carlos Vitor Medeiros | E33: 2 | F33: Christian Gomes Gonçalves | G33: 2 | H33: Arthur Gabriel
A34: 3 | B34: Anny Beatriz Machado Lopes | C34: 3 | D34: Juliana Lopes Fernandes | E34: 3 | F34: David Martins Alves | G34: 3 | H34: Cícero Bezerra
A35: 4 | B35: Gleibe Santana Marques | C35: 4 | D35: Leilany Medeiros | E35: 4 | F35: Edvaldo Francelino Martins | G35: 4 | H35: Denes Pereira dos Santos
A36: 5 | B36: Jair Marques | C36: 5 | D36: Leonel Mangabeira | E36: 5 | F36: Elaine Lessa Silva | G36: 5 | H36: Eurides Freitas Merquiades
A37: 6 | B37: Laura Santana Marques | C37: 6 | D37: Maria Claudia Almeida | E37: 6 | F37: Eliane Lessa Martins | G37: 6 | H37: Inácio Manoel da Silva Filho
A38: 7 | B38: Leonildo de Carvalho Jr | C38: 7 | D38: Maria do Carmo S. de Almeida | E38: 7 | F38: Francisca Binas | G38: 7 | H38: Jaqueline Bezerra
A39: 8 | B39: Maria José de Vasconcelos (Zeza) | C39: 8 | D39: Marli Santos de Almeida | E39: 8 | F39: Francisco Pereira da Silva | G39: 8 | H39: José Cristian Joseph
A40: 9 | B40: Moisés Caetano | C40: 9 | D40: Marta Eliane de Almeida | E40: 9 | F40: Jackson Araujo do Nascimento | G40: 9 | H40: José Marcos Lira
A41: 10 | B41: Paulo Campos | C41: 10 | D41: Maura Mangabeiras de Araújo | E41: 10 | F41: José Ailton Santana Alves | G41: 10 | H41: Maria Madalena Rocha Silva
A42: 11 | B42: Rafaela Campos | C42: 11 | D42: Monique (PNB) | E42: 11 | F42: Maria Quitéria da Silva Alves | G42: 11 | H42: Miguel Levi
A43: 12 | B43: Zarmânio Ferreira Cavalcante | C43: 12 | D43: Patrícia Vieira | E43: 12 | F43: Maria Rosimeire C. (Rosa - Edson) | G43: 12 | H43: Paulina da Silva Lopes
C44: 13 | D44: Selma Santos de Almeida | E44: 13 | F44: Maria Sebastiana Bertoldo Araújo | G44: 13 | H44: Pedro Oliveira
...

Sheet APROVADOS
B1: INDICADORES | C1: MIC. VOL. | D1: PALCO | E1: MIDIA | F1: LEITORES | G1: PRESIDENTES
A4: 1 | G4: ARNALDO
A5: 2 | G5: JOSÉ AILTON
A6: 3 | G6: ALMIR FERNANDES
A7: 4 | G7: DENIS PEREIRA
A8: 6 | G8: FABIANO CORREIA
A9: 7 | G9: FABRÍCIO FÉLIX
A10: 8 | G10: GEORGETOWN
A11: 9 | G11: LEONILDO JR.
A12: 10 | G12: LÚCIO ALMEIDA
A13: 11 | G13: OLIVEIROS ALMEIDA
A14: 12 | G14: PEDRO
A15: 13 | G15: VITOR MEDEIROS
... A17: 15 | G17: MAURÍCIO BELLO
A18: 16 | B18: JOÃO CAVALCANTE | E18: JOÃO CAVALCANTE | F18: JOÃO CAVALCANTE | G18: JOÃO CAVALCANTE
B19: ALAN | C19: ALAN | D19: ALAN
A20: 17 | B20: BRUNO REIS | E20: BRUNO REIS | F20: BRUNO REIS | G20: BRUNO REIS
A21: 18 | B21: JEAN LUCAS | E21: JEAN LUCAS | F21: JEAN LUCAS | G21: JEAN LUCAS
A22: 19 | B22: LEONEL MANGAB. | C22: LEONEL MANGAB. | D22: LEONEL MANGAB. | F22: LEONEL MANGAB. | G22: LEONEL MANGAB.
A23: 20 | B23: JHOSEF SILVA | E23: JHOSEF SILVA | G23: JHOSEF SILVA
A24: 21 | B24: MOISÉS CAETANO | C24: MOISÉS CAETANO | D24: MOISÉS CAETANO | G24: MOISÉS CAETANO
A25: 22 | B25: TÉRCIO ALMEIDA | C25: TÉRCIO ALMEIDA | D25: TÉRCIO ALMEIDA | G25: TÉRCIO ALMEIDA
A26: 23 | B26: ISRAEL FÉLIX | C26: ISRAEL FÉLIX | D26: ISRAEL FÉLIX
A27: 24 | B27: FRED PACHECO | E27: FRED PACHECO | F27: FRED PACHECO | G27: FRED PACHECO
A28: 25 | B28: INÁCIO SILVA | C28: INÁCIO SILVA | D28: INÁCIO SILVA
A29: 26 | B29: DENILSON REIS | E29: DENILSON REIS | F29: DENILSON REIS | G29: DENILSON REIS
A30: 27 | B30: EDVALDO MARTINS | C30: EDVALDO MARTINS | D30: EDVALDO MARTINS
A31: 28 | B31: PETRÚCIO | C31: PETRÚCIO | D31: PETRÚCIO
A32: 29 | B32: JACKSON ARAÚJO | C32: JACKSON ARAÚJO | D32: JACKSON ARAÚJO
A33: 32 | C33: GASPAR BELLO | D33: GASPAR BELLO
A34: 33 | C34: DANIEL | D34: DANIEL | E34: DANIEL
A35: 34 | C35: DAVID ALVES
